Workbook

Sheet Excluded_Terms
A1: {=_xlfn._xlws.FILTER(sonificationORaudification!A1:'sonificationORaudification'!A202,(sonificationORaudification!C1:'sonificationORaudification'!C202="N")*(sonificationORaudification!G1:'sonificationORaudification'!G202="Missing"))} -> Mycotoxins in Agriculture and Food | B1: {=_xlfn._xlws.FILTER(allTerms!A1:'allTerms'!A202,(allTerms!C1:'allTerms'!C202="N"))} -> Ultrasound and Cavitation Phenomena
A2: Adsorption and biosorption for pollutant removal | B2: Ultrasound and Hyperthermia Applications
A3: Nanoparticle-Based Drug Delivery | B3: Carbon Nanotubes in Composites
A4: Luminescence Properties of Advanced Materials | B4: Advanced Polymer Synthesis and Characterization
A5: Drug Solubulity and Delivery Systems | B5: Ultrasonics and Acoustic Wave Propagation
A6: Immune Response and Inflammation | B6: Analytical chemistry methods development
A7: Postharvest Quality and Shelf Life Management | B7: Anaerobic Digestion and Biogas Production
A8: Ion channel regulation and function | B8: Algal biology and biofuel production
A9: Advanced Proteomics Techniques and Applications | B9: Photosynthetic Processes and Mechanisms
A10: Bacterial biofilms and quorum sensing | B10: Advanced Cellulose Research Studies
A11: Surfactants and Colloidal Systems | B11: Lipid Membrane Structure and Behavior
A12: RNA Interference and Gene Delivery | B12: Soil and Unsaturated Flow
A13: Platelet Disorders and Treatments | B13: Biodiesel Production and Applications
A14: Advanced Drug Delivery Systems | B14: Acoustic Wave Phenomena Research
B15: Orthopedic Infections and Treatments
B16: Soil Carbon and Nitrogen Dynamics
B17: Nanofluid Flow and Heat Transfer
B18: Aquatic Ecosystems and Phytoplankton Dynamics
B19: Oral microbiology and periodontitis research
B20: Mitochondrial Function and Pathology
B21: Polymer Nanocomposites and Properties
B22: biodegradable polymer synthesis and properties
B23: Cinema and Media Studies
B24: Underwater Vehicles and Communication Systems
B25: Membrane Separation Technologies
B26: Essential Oils and Antimicrobial Activity
... B57: Bee Products Chemical Analysis

Sheet allTerms
A1: name | B1: count | C1: Include? | D1: Note
A2: Tactile and Sensory Interactions | B2: 1456 | C2: =VLOOKUP(A2,sonificationORaudification!$A:$D, 3, FALSE) -> Y | D2: =VLOOKUP(A2,sonificationORaudification!$A:$D, 4, FALSE) -> 0
A3: Music Technology and Sound Studies | B3: 906 | C3: =VLOOKUP(A3,sonificationORaudification!$A:$D, 3, FALSE) -> Y | D3: =VLOOKUP(A3,sonificationORaudification!$A:$D, 4, FALSE) -> 0
A4: Hearing Loss and Rehabilitation | B4: 255 | C4: =VLOOKUP(A4,sonificationORaudification!$A:$D, 3, FALSE) -> Y | D4: =VLOOKUP(A4,sonificationORaudification!$A:$D, 4, FALSE) -> Chris: Includes sonification handbook! Carol: papers broader than topic would suggest and include sonification
A5: Human-Automation Interaction and Safety | B5: 233 | C5: =VLOOKUP(A5,sonificationORaudification!$A:$D, 3, FALSE) -> Y | D5: =VLOOKUP(A5,sonificationORaudification!$A:$D, 4, FALSE) -> 0
A6: Multisensory perception and integration | B6: 164 | C6: =VLOOKUP(A6,sonificationORaudification!$A:$D, 3, FALSE) -> Y | D6: =VLOOKUP(A6,sonificationORaudification!$A:$D, 4, FALSE) -> 0
A7: Music and Audio Processing | B7: 155 | C7: =VLOOKUP(A7,sonificationORaudification!$A:$D, 3, FALSE) -> Y | D7: =VLOOKUP(A7,sonificationORaudification!$A:$D, 4, FALSE) -> 0
A8: Noise Effects and Management | B8: 141 | C8: =VLOOKUP(A8,sonificationORaudification!$A:$D, 3, FALSE) -> Y | D8: =VLOOKUP(A8,sonificationORaudification!$A:$D, 4, FALSE) -> 0
A9: Data Visualization and Analytics | B9: 129 | C9: =VLOOKUP(A9,sonificationORaudification!$A:$D, 3, FALSE) -> Y | D9: =VLOOKUP(A9,sonificationORaudification!$A:$D, 4, FALSE) -> 0
A10: EEG and Brain-Computer Interfaces | B10: 118 | C10: =VLOOKUP(A10,sonificationORaudification!$A:$D, 3, FALSE) -> Y | D10: =VLOOKUP(A10,sonificationORaudification!$A:$D, 4, FALSE) -> 0
A11: Healthcare Technology and Patient Monitoring | B11: 103 | C11: =VLOOKUP(A11,sonificationORaudification!$A:$D, 3, FALSE) -> Y | D11: =VLOOKUP(A11,sonificationORaudification!$A:$D, 4, FALSE) -> Although, as might be expected quite a few papers about using sonification of bodily measurements to monitor patients' condition
A12: Neuroscience and Music Perception | B12: 92 | C12: =VLOOKUP(A12,sonificationORaudification!$A:$D, 3, FALSE) -> Y | D12: =VLOOKUP(A12,sonificationORaudification!$A:$D, 4, FALSE) -> 0
A13: Innovative Human-Technology Interaction | B13: 82 | C13: =VLOOKUP(A13,sonificationORaudification!$A:$D, 3, FALSE) -> Y | D13: =VLOOKUP(A13,sonificationORaudification!$A:$D, 4, FALSE) -> 0
... A70: Advanced Optical Imaging Technologies | B70: 11 | C70: =VLOOKUP(A70,sonificationORaudification!$A:$D, 3, FALSE) -> Y | D70: =VLOOKUP(A70,sonificationORaudification!$A:$D, 4, FALSE) -> 0
A71: Spatial Cognition and Navigation | B71: 11 | C71: Y | D71: -
A72: Personal Information Management and User Behavior | B72: 11 | C72: =VLOOKUP(A72,sonificationORaudification!$A:$D, 3, FALSE) -> Y | D72: =VLOOKUP(A72,sonificationORaudification!$A:$D, 4, FALSE) -> 0
A73: Visual Culture and Art Theory | B73: 11 | C73: =VLOOKUP(A73,sonificationORaudification!$A:$D, 3, FALSE) -> Y | D73: =VLOOKUP(A73,sonificationORaudification!$A:$D, 4, FALSE) -> 0
A74: Space Science and Extraterrestrial Life | B74: 11 | C74: =VLOOKUP(A74,sonificationORaudification!$A:$D, 3, FALSE) -> Y | D74: =VLOOKUP(A74,sonificationORaudification!$A:$D, 4, FALSE) -> 0
A75: History and Developments in Astronomy | B75: 11 | C75: =VLOOKUP(A75,sonificationORaudification!$A:$D, 3, FALSE) -> Y | D75: =VLOOKUP(A75,sonificationORaudification!$A:$D, 4, FALSE) -> 0
A76: Cybernetics and Technology in Society | B76: 11 | C76: =VLOOKUP(A76,sonificationORaudification!$A:$D, 3, FALSE) -> Y | D76: =VLOOKUP(A76,sonificationORaudification!$A:$D, 4, FALSE) -> 0
A77: Media, Communication, and Education | B77: 11 | C77: =VLOOKUP(A77,sonificationORaudification!$A:$D, 3, FALSE) -> Y | D77: =VLOOKUP(A77,sonificationORaudification!$A:$D, 4, FALSE) -> 0
A78: Photosynthetic Processes and Mechanisms | B78: 10 | C78: =VLOOKUP(A78,sonificationORaudification!$A:$D, 3, FALSE) -> N | D78: =VLOOKUP(A78,sonificationORaudification!$A:$D, 4, FALSE) -> 0
A79: Advanced Cellulose Research Studies | B79: 10 | C79: =VLOOKUP(A79,sonificationORaudification!$A:$D, 3, FALSE) -> N | D79: =VLOOKUP(A79,sonificationORaudification!$A:$D, 4, FALSE) -> 0
A80: Quantum Mechanics and Applications | B80: 10 | C80: =VLOOKUP(A80,sonificationORaudification!$A:$D, 3, FALSE) -> Y | D80: =VLOOKUP(A80,sonificationORaudification!$A:$D, 4, FALSE) -> 0
A81: Geographies of human-animal interactions | B81: 10 | C81: =VLOOKUP(A81,sonificationORaudification!$A:$D, 3, FALSE) -> Y | D81: =VLOOKUP(A81,sonificationORaudification!$A:$D, 4, FALSE) -> 0
A82: Machine Learning in Materials Science | B82: 10 | C82: =VLOOKUP(A82,sonificationORaudification!$A:$D, 3, FALSE) -> Y | D82: =VLOOKUP(A82,sonificationORaudification!$A:$D, 4, FALSE) -> 0
A83: Slime Mold and Myxomycetes Research | B83: 10 | C83: =VLOOKUP(A83,sonificationORaudification!$A:$D, 3, FALSE) -> Y | D83: =VLOOKUP(A83,sonificationORaudification!$A:$D, 4, FALSE) -> 0
... A85: Soil and Unsaturated Flow | B85: 9 | C85: =VLOOKUP(A85,sonificationORaudification!$A:$D, 3, FALSE) -> N | D85: =VLOOKUP(A85,sonificationORaudification!$A:$D, 4, FALSE) -> 0
A86: Visual and Cognitive Learning Processes | B86: 9 | C86: Y | D86: -
A87: Ergonomics and Musculoskeletal Disorders | B87: 9 | C87: Y | D87: -
A88: Diversity and Impact of Dance | B88: 9 | C88: =VLOOKUP(A88,sonificationORaudification!$A:$D, 3, FALSE) -> Y | D88: =VLOOKUP(A88,sonificationORaudification!$A:$D, 4, FALSE) -> If we are including sonification of movement
A89: Seismology and Earthquake Studies | B89: 9 | C89: =VLOOKUP(A89,sonificationORaudification!$A:$D, 3, FALSE) -> Y | D89: =VLOOKUP(A89,sonificationORaudification!$A:$D, 4, FALSE) -> 0
A90: Artistic and Creative Research | B90: 9 | C90: =VLOOKUP(A90,sonificationORaudification!$A:$D, 3, FALSE) -> Y | D90: =VLOOKUP(A90,sonificationORaudification!$A:$D, 4, FALSE) -> 0
A91: Radio, Podcasts, and Digital Media | B91: 9 | C91: =VLOOKUP(A91,sonificationORaudification!$A:$D, 3, FALSE) -> Y | D91: =VLOOKUP(A91,sonificationORaudification!$A:$D, 4, FALSE) -> 0
A92: Sound Studies and Aurality | B92: 9 | C92: =VLOOKUP(A92,sonificationORaudification!$A:$D, 3, FALSE) -> Y | D92: =VLOOKUP(A92,sonificationORaudification!$A:$D, 4, FALSE) -> 0
A93: Art, Technology, and Culture | B93: 9 | C93: =VLOOKUP(A93,sonificationORaudification!$A:$D, 3, FALSE) -> Y | D93: =VLOOKUP(A93,sonificationORaudification!$A:$D, 4, FALSE) -> 0
A94: Usability and User Interface Design | B94: 8 | C94: =VLOOKUP(A94,sonificationORaudification!$A:$D, 3, FALSE) -> Y | D94: =VLOOKUP(A94,sonificationORaudification!$A:$D, 4, FALSE) -> 0
A95: Biodiesel Production and Applications | B95: 8 | C95: =VLOOKUP(A95,sonificationORaudification!$A:$D, 3, FALSE) -> N | D95: =VLOOKUP(A95,sonificationORaudification!$A:$D, 4, FALSE) -> 0
A96: Posthumanist Ethics and Activism | B96: 8 | C96: =VLOOKUP(A96,sonificationORaudification!$A:$D, 3, FALSE) -> Y | D96: =VLOOKUP(A96,sonificationORaudification!$A:$D, 4, FALSE) -> 0
A97: Acoustic Wave Phenomena Research | B97: 8 | C97: =VLOOKUP(A97,sonificationORaudification!$A:$D, 3, FALSE) -> N | D97: =VLOOKUP(A97,sonificationORaudification!$A:$D, 4, FALSE) -> 0
...

Sheet sonificationORaudification
A1: name | B1: count | C1: Include? | D1: Note | G1: in allTerms?
A2: Tactile and Sensory Interactions | B2: 1119 | C2: Y | G2: =IF(ISNA(VLOOKUP(A2,allTerms!$A$2:$A$201, 1, FALSE)), "Missing", "Found") -> Found
A3: Music Technology and Sound Studies | B3: 710 | C3: Y | G3: =IF(ISNA(VLOOKUP(A3,allTerms!$A$2:$A$201, 1, FALSE)), "Missing", "Found") -> Found
A4: Data Visualization and Analytics | B4: 109 | C4: Y | G4: =IF(ISNA(VLOOKUP(A4,allTerms!$A$2:$A$201, 1, FALSE)), "Missing", "Found") -> Found | L4: {=_xlfn._xlws.FILTER(A1:A202,C1:C202="N")} -> Ultrasound and Cavitation Phenomena
A5: Multisensory perception and integration | B5: 106 | C5: Y | G5: =IF(ISNA(VLOOKUP(A5,allTerms!$A$2:$A$201, 1, FALSE)), "Missing", "Found") -> Found | L5: Ultrasound and Hyperthermia Applications
A6: Music and Audio Processing | B6: 104 | C6: Y | G6: =IF(ISNA(VLOOKUP(A6,allTerms!$A$2:$A$201, 1, FALSE)), "Missing", "Found") -> Found | L6: Carbon Nanotubes in Composites
A7: EEG and Brain-Computer Interfaces | B7: 96 | C7: Y | G7: =IF(ISNA(VLOOKUP(A7,allTerms!$A$2:$A$201, 1, FALSE)), "Missing", "Found") -> Found | L7: Analytical chemistry methods development
A8: Neuroscience and Music Perception | B8: 69 | C8: Y | G8: =IF(ISNA(VLOOKUP(A8,allTerms!$A$2:$A$201, 1, FALSE)), "Missing", "Found") -> Found | L8: Anaerobic Digestion and Biogas Production
A9: Noise Effects and Management | B9: 68 | C9: Y | G9: =IF(ISNA(VLOOKUP(A9,allTerms!$A$2:$A$201, 1, FALSE)), "Missing", "Found") -> Found | L9: Advanced Polymer Synthesis and Characterization
A10: Plant and Biological Electrophysiology Studies | B10: 62 | C10: Y | D10: Topic title doesn't seem to have much to do with the papers which do include ones on sonification | G10: =IF(ISNA(VLOOKUP(A10,allTerms!$A$2:$A$201, 1, FALSE)), "Missing", "Found") -> Found | L10: Advanced Cellulose Research Studies
A11: Action Observation and Synchronization | B11: 53 | C11: y | G11: =IF(ISNA(VLOOKUP(A11,allTerms!$A$2:$A$201, 1, FALSE)), "Missing", "Found") -> Found | L11: Biodiesel Production and Applications
A12: Healthcare Technology and Patient Monitoring | B12: 50 | C12: Y | D12: Although, as might be expected quite a few papers about using sonification of bodily measurements to monitor patients' condition | G12: =IF(ISNA(VLOOKUP(A12,allTerms!$A$2:$A$201, 1, FALSE)), "Missing", "Found") -> Found | L12: biodegradable polymer synthesis and properties
A13: Innovative Human-Technology Interaction | B13: 49 | C13: Y | G13: =IF(ISNA(VLOOKUP(A13,allTerms!$A$2:$A$201, 1, FALSE)), "Missing", "Found") -> Found | L13: Soil and Unsaturated Flow
A14: Diverse Musicological Studies | B14: 49 | C14: Y | G14: =IF(ISNA(VLOOKUP(A14,allTerms!$A$2:$A$201, 1, FALSE)), "Missing", "Found") -> Found | L14: Orthopedic Infections and Treatments
A15: Human-Automation Interaction and Safety | B15: 37 | C15: Y | G15: =IF(ISNA(VLOOKUP(A15,allTerms!$A$2:$A$201, 1, FALSE)), "Missing", "Found") -> Found | L15: Nanofluid Flow and Heat Transfer
A16: Music Therapy and Health | B16: 36 | C16: Y | D16: Quite a lot about moving to sounds for rehabilitation | G16: =IF(ISNA(VLOOKUP(A16,allTerms!$A$2:$A$201, 1, FALSE)), "Missing", "Found") -> Found | L16: Photosynthetic Processes and Mechanisms
A17: Design Education and Practice | B17: 31 | C17: y | G17: =IF(ISNA(VLOOKUP(A17,allTerms!$A$2:$A$201, 1, FALSE)), "Missing", "Found") -> Found | L17: Algal biology and biofuel production
A18: Ultrasound and Cavitation Phenomena | B18: 29 | C18: N | G18: =IF(ISNA(VLOOKUP(A18,allTerms!$A$2:$A$201, 1, FALSE)), "Missing", "Found") -> Found | L18: Soil Carbon and Nitrogen Dynamics
A19: Interactive and Immersive Displays | B19: 22 | C19: Y | G19: =IF(ISNA(VLOOKUP(A19,allTerms!$A$2:$A$201, 1, FALSE)), "Missing", "Found") -> Found | L19: Membrane Separation Technologies
A20: Virtual Reality Applications and Impacts | B20: 21 | C20: Y | G20: =IF(ISNA(VLOOKUP(A20,allTerms!$A$2:$A$201, 1, FALSE)), "Missing", "Found") -> Found | L20: Essential Oils and Antimicrobial Activity
A21: Ultrasound and Hyperthermia Applications | B21: 20 | C21: N | G21: =IF(ISNA(VLOOKUP(A21,allTerms!$A$2:$A$201, 1, FALSE)), "Missing", "Found") -> Found | L21: Polymer Nanocomposites and Properties
A22: Underwater Acoustics Research | B22: 20 | C22: Y | D22: some of the papers are sonification of ocean data | G22: =IF(ISNA(VLOOKUP(A22,allTerms!$A$2:$A$201, 1, FALSE)), "Missing", "Found") -> Found | L22: Ultrasonics and Acoustic Wave Propagation
A23: Architecture and Computational Design | B23: 20 | C23: Y | G23: =IF(ISNA(VLOOKUP(A23,allTerms!$A$2:$A$201, 1, FALSE)), "Missing", "Found") -> Found | L23: Phytochemicals and Antioxidant Activities
A24: Neural dynamics and brain function | B24: 19 | C24: Y | G24: =IF(ISNA(VLOOKUP(A24,allTerms!$A$2:$A$201, 1, FALSE)), "Missing", "Found") -> Found | L24: Advanced Photocatalysis Techniques
A25: 3D Surveying and Cultural Heritage | B25: 19 | C25: Y | G25: =IF(ISNA(VLOOKUP(A25,allTerms!$A$2:$A$201, 1, FALSE)), "Missing", "Found") -> Found | L25: Supercapacitor Materials and Fabrication
A26: Vehicle Noise and Vibration Control | B26: 19 | C26: Y | D26: Mix of using sound in electric cars, but also sonification of data from cars | G26: =IF(ISNA(VLOOKUP(A26,allTerms!$A$2:$A$201, 1, FALSE)), "Missing", "Found") -> Found | L26: Oral microbiology and periodontitis research
A27: Stroke Rehabilitation and Recovery | B27: 18 | C27: Y | D27: sonification in rehab | G27: =IF(ISNA(VLOOKUP(A27,allTerms!$A$2:$A$201, 1, FALSE)), "Missing", "Found") -> Found | L27: Lipid Membrane Structure and Behavior
A28: Advanced Chemical Sensor Technologies | B28: 18 | C28: Y | D28: contains a few papers which are sonication, but also some sonification | G28: =IF(ISNA(VLOOKUP(A28,allTerms!$A$2:$A$201, 1, FALSE)), "Missing", "Found") -> Found | L28: Natural Fiber Reinforced Composites
A29: Time Series Analysis and Forecasting | B29: 18 | C29: Y | G29: =IF(ISNA(VLOOKUP(A29,allTerms!$A$2:$A$201, 1, FALSE)), "Missing", "Found") -> Found | L29: Cinema and Media Studies
A30: Phonocardiography and Auscultation Techniques | B30: 18 | C30: y | G30: =IF(ISNA(VLOOKUP(A30,allTerms!$A$2:$A$201, 1, FALSE)), "Missing", "Found") -> Found | L30: Analytical Chemistry and Chromatography
A31: Hearing Loss and Rehabilitation | B31: 16 | C31: Y | D31: Chris: Includes sonification handbook! Carol: papers broader than topic would suggest and include sonification | G31: =IF(ISNA(VLOOKUP(A31,allTerms!$A$2:$A$201, 1, FALSE)), "Missing", "Found") -> Found | L31: Phase Change Materials Research
A32: Augmented Reality Applications | B32: 16 | C32: Y | G32: =IF(ISNA(VLOOKUP(A32,allTerms!$A$2:$A$201, 1, FALSE)), "Missing", "Found") -> Found | L32: Clay minerals and soil interactions
A33: Balance, Gait, and Falls Prevention | B33: 14 | C33: Y | G33: =IF(ISNA(VLOOKUP(A33,allTerms!$A$2:$A$201, 1, FALSE)), "Missing", "Found") -> Found | L33: Food Quality and Safety Studies
A34: ECG Monitoring and Analysis | B34: 14 | C34: y | G34: =IF(ISNA(VLOOKUP(A34,allTerms!$A$2:$A$201, 1, FALSE)), "Missing", "Found") -> Found | L34: Electrohydrodynamics and Fluid Dynamics
A35: Computational Physics and Python Applications | B35: 14 | C35: y | G35: =IF(ISNA(VLOOKUP(A35,allTerms!$A$2:$A$201, 1, FALSE)), "Missing", "Found") -> Found | L35: Material Properties and Applications
A36: Cognitive Science and Education Research | B36: 14 | C36: y | G36: =IF(ISNA(VLOOKUP(A36,allTerms!$A$2:$A$201, 1, FALSE)), "Missing", "Found") -> Found | L36: Natural Products and Applications
A37: Carbon Nanotubes in Composites | B37: 13 | C37: N | G37: =IF(ISNA(VLOOKUP(A37,allTerms!$A$2:$A$201, 1, FALSE)), "Missing", "Found") -> Found | L37: Advancements in Battery Materials
A38: Teleoperation and Haptic Systems | B38: 13 | C38: y | G38: =IF(ISNA(VLOOKUP(A38,allTerms!$A$2:$A$201, 1, FALSE)), "Missing", "Found") -> Found | L38: Neuroscience and Neuropharmacology Research
A39: Human Motion and Animation | B39: 13 | C39: y | G39: =IF(ISNA(VLOOKUP(A39,allTerms!$A$2:$A$201, 1, FALSE)), "Missing", "Found") -> Found | L39: Nanoparticles: synthesis and applications
A40: Analytical chemistry methods development | B40: 12 | C40: N | G40: =IF(ISNA(VLOOKUP(A40,allTerms!$A$2:$A$201, 1, FALSE)), "Missing", "Found") -> Found | L40: Graphene research and applications
...
